
<robot
  name="fedar">
  <link
    name="base_link">
    <inertial>
      <origin
        xyz="-0.046264 0.28187 0.0076913"
        rpy="0 0 0" />
      <mass
        value="10.987" />
      <inertia
        ixx="1.7088"
        ixy="-0.16847"
        ixz="-0.0063516"
        iyy="0.42468"
        iyz="0.02647"
        izz="1.7946" />
    </inertial>
    <visual>
      <origin
        xyz="0 0 0"
        rpy="0 0 0" />
      <geometry>
        <mesh
          filename="package://fedar/meshes/base_link.STL" />
      </geometry>
      <material
        name="">
        <color
          rgba="0.75294 0.75294 0.75294 1" />
      </material>
    </visual>
    <collision>
      <origin
        xyz="0 0 0"
        rpy="0 0 0" />
      <geometry>
        <mesh
          filename="package://fedar/meshes/base_link.STL" />
      </geometry>
    </collision>
  </link>
  <link
    name="left_drive_wheel_link">
    <inertial>
      <origin
        xyz="-0.026967 5.5273E-10 -1.0367E-09"
        rpy="0 0 0" />
      <mass
        value="2.1634" />
      <inertia
        ixx="0.032586"
        ixy="2.9603E-12"
        ixz="9.9332E-11"
        iyy="0.016643"
        iyz="-1.5958E-10"
        izz="0.016643" />
    </inertial>
    <visual>
      <origin
        xyz="0 0 0"
        rpy="0 0 0" />
      <geometry>
        <mesh
          filename="package://fedar/meshes/left_drive_wheel_link.STL" />
      </geometry>
      <material
        name="">
        <color
          rgba="0.29412 0.29412 0.29412 1" />
      </material>
    </visual>
    <collision>
      <origin
        xyz="0 0 0"
        rpy="0 0 0" />
      <geometry>
        <mesh
          filename="package://fedar/meshes/left_drive_wheel_link.STL" />
      </geometry>
    </collision>
  </link>
  <joint
    name="left_drive_wheel_joint"
    type="continuous">
    <origin
      xyz="-0.24 -0.249 -0.055"
      rpy="1.5708 6.123E-17 1.5708" />
    <parent
      link="base_link" />
    <child
      link="left_drive_wheel_link" />
    <axis
      xyz="1 0 0" />
  </joint>
  <link
    name="right_drive_wheel_link">
    <inertial>
      <origin
        xyz="0.0270334407669869 5.52729494118775E-10 -1.03672306850378E-09"
        rpy="0 0 0" />
      <mass
        value="2.16344839685526" />
      <inertia
        ixx="0.0325861513561255"
        ixy="2.9603479359812E-12"
        ixz="9.93315789171524E-11"
        iyy="0.0166433812823134"
        iyz="-1.59581006700158E-10"
        izz="0.0166433811644508" />
    </inertial>
    <visual>
      <origin
        xyz="0 0 0"
        rpy="0 0 0" />
      <geometry>
        <mesh
          filename="package://fedar/meshes/right_drive_wheel_link.STL" />
      </geometry>
      <material
        name="">
        <color
          rgba="0.294117647058824 0.294117647058824 0.294117647058824 1" />
      </material>
    </visual>
    <collision>
      <origin
        xyz="0 0 0"
        rpy="0 0 0" />
      <geometry>
        <mesh
          filename="package://fedar/meshes/right_drive_wheel_link.STL" />
      </geometry>
    </collision>
  </link>
  <joint
    name="right_drive_wheel_joint"
    type="continuous">
    <origin
      xyz="-0.24 0.249 -0.055"
      rpy="1.5708 6.123E-17 1.5708" />
    <parent
      link="base_link" />
    <child
      link="right_drive_wheel_link" />
    <axis
      xyz="1 0 0" />
  </joint>
  <link
    name="left_trolley_wheel_bracket_link">
    <inertial>
      <origin
        xyz="0.0247635408908801 0.0818790644900511 -8.32667268468867E-17"
        rpy="0 0 0" />
      <mass
        value="0.0275781208850641" />
      <inertia
        ixx="4.49789834181829E-05"
        ixy="-1.24410071792927E-05"
        ixz="1.01594092944541E-20"
        iyy="2.08578618373714E-05"
        iyz="-1.97182783543518E-20"
        izz="4.21017425184769E-05" />
    </inertial>
    <visual>
      <origin
        xyz="0 0 0"
        rpy="0 0 0" />
      <geometry>
        <mesh
          filename="package://fedar/meshes/left_trolley_wheel_bracket_link.STL" />
      </geometry>
      <material
        name="">
        <color
          rgba="0.752941176470588 0.752941176470588 0.752941176470588 1" />
      </material>
    </visual>
    <collision>
      <origin
        xyz="0 0 0"
        rpy="0 0 0" />
      <geometry>
        <mesh
          filename="package://fedar/meshes/left_trolley_wheel_bracket_link.STL" />
      </geometry>
    </collision>
  </link>
  <joint
    name="left_trolley_wheel_bracket_joint"
    type="continuous">
    <origin
      xyz="0.22374 -0.21 -0.115"
      rpy="1.5708 0 0" />
    <parent
      link="base_link" />
    <child
      link="left_trolley_wheel_bracket_link" />
    <axis
      xyz="0 -1 0" />
  </joint>
  <link
    name="left_trolley_wheel_link">
    <inertial>
      <origin
        xyz="-0.0104923842827915 5.3143839329195E-10 1.28055210879552E-09"
        rpy="0 0 0" />
      <mass
        value="0.29264656535805" />
      <inertia
        ixx="0.000978801985309353"
        ixy="-4.80647721975069E-13"
        ixz="-3.6446409811643E-12"
        iyy="0.000502580759463228"
        iyz="-8.11291518075436E-12"
        izz="0.000502580756909004" />
    </inertial>
    <visual>
      <origin
        xyz="0 0 0"
        rpy="0 0 0" />
      <geometry>
        <mesh
          filename="package://fedar/meshes/left_trolley_wheel_link.STL" />
      </geometry>
      <material
        name="">
        <color
          rgba="0.294117647058824 0.294117647058824 0.294117647058824 1" />
      </material>
    </visual>
    <collision>
      <origin
        xyz="0 0 0"
        rpy="0 0 0" />
      <geometry>
        <mesh
          filename="package://fedar/meshes/left_trolley_wheel_link.STL" />
      </geometry>
    </collision>
  </link>
  <joint
    name="left_trolley_wheel_joint"
    type="continuous">
    <origin
      xyz="0.05151 0.01 0"
      rpy="0 -1.5708 0" />
    <parent
      link="left_trolley_wheel_bracket_link" />
    <child
      link="left_trolley_wheel_link" />
    <axis
      xyz="-1 0 0" />
  </joint>

  <link
    name="right_trolley_wheel_bracket_link">
    <inertial>
      <origin
        xyz="0.0135069472412436 -0.0331209355099489 -8.32667268468867E-17"
        rpy="0 0 0" />
      <mass
        value="0.0275781208850641" />
      <inertia
        ixx="4.49789834181828E-05"
        ixy="-1.24410071792927E-05"
        ixz="1.41074330389317E-20"
        iyy="2.08578618373713E-05"
        iyz="6.76613231629152E-21"
        izz="4.21017425184768E-05" />
    </inertial>
    <visual>
      <origin
        xyz="0 0 0"
        rpy="0 0 0" />
      <geometry>
        <mesh
          filename="package://fedar/meshes/right_trolley_wheel_bracket_link.STL" />
      </geometry>
      <material
        name="">
        <color
          rgba="0.752941176470588 0.752941176470588 0.752941176470588 1" />
      </material>
    </visual>
    <collision>
      <origin
        xyz="0 0 0"
        rpy="0 0 0" />
      <geometry>
        <mesh
          filename="package://fedar/meshes/right_trolley_wheel_bracket_link.STL" />
      </geometry>
    </collision>
  </link>
  <joint
    name="right_trolley_wheel_bracket_joint"
    type="continuous">
    <origin
      xyz="0.235 0.21 0"
      rpy="1.5708 0 0" />
    <parent
      link="base_link" />
    <child
      link="right_trolley_wheel_bracket_link" />
    <axis
      xyz="0 -1 0" />
  </joint>
  <link
    name="right_trolley_wheel_link">
    <inertial>
      <origin
        xyz="-0.0104923842827914 -5.31438337780799E-10 -1.28055210879552E-09"
        rpy="0 0 0" />
      <mass
        value="0.29264656535805" />
      <inertia
        ixx="0.000978801985309353"
        ixy="4.80647808889687E-13"
        ixz="3.64464071291266E-12"
        iyy="0.000502580759463228"
        iyz="-8.1129151113064E-12"
        izz="0.000502580756909004" />
    </inertial>
    <visual>
      <origin
        xyz="0 0 0"
        rpy="0 0 0" />
      <geometry>
        <mesh
          filename="package://fedar/meshes/right_trolley_wheel_link.STL" />
      </geometry>
      <material
        name="">
        <color
          rgba="0.294117647058824 0.294117647058824 0.294117647058824 1" />
      </material>
    </visual>
    <collision>
      <origin
        xyz="0 0 0"
        rpy="0 0 0" />
      <geometry>
        <mesh
          filename="package://fedar/meshes/right_trolley_wheel_link.STL" />
      </geometry>
    </collision>
  </link>
  <joint
    name="right_trolley_wheel_joint"
    type="continuous">
    <origin
      xyz="0.040253 -0.105 0"
      rpy="2.7485 1.5708 0" />
    <parent
      link="right_trolley_wheel_bracket_link" />
    <child
      link="right_trolley_wheel_link" />
    <axis
      xyz="1 0 0" />
  </joint>

  <link
    name="upper_arm_link">
    <inertial>
      <origin
        xyz="0.20011 2.857E-10 0.0065338"
        rpy="0 0 0" />
      <mass
        value="0.81497" />
      <inertia
        ixx="0.0021672"
        ixy="6.1685E-12"
        ixz="-1.3371E-11"
        iyy="0.01654"
        iyz="2.7308E-12"
        izz="0.015662" />
    </inertial>
    <visual>
      <origin
        xyz="0 0 0"
        rpy="0 0 0" />
      <geometry>
        <mesh
          filename="package://fedar/meshes/upper_arm_link.STL" />
      </geometry>
      <material
        name="">
        <color
          rgba="0.69804 1 0.69804 1" />
      </material>
    </visual>
    <collision>
      <origin
        xyz="0 0 0"
        rpy="0 0 0" />
      <geometry>
        <mesh
          filename="package://fedar/meshes/upper_arm_link.STL" />
      </geometry>
    </collision>
  </link>
  <joint
    name="upper_arm_joint"
    type="revolute">
    <origin
      xyz="0 0.015 0.9915"
      rpy="1.5708 -1.11746 -1.5708" />
    <parent
      link="base_link" />
    <child
      link="upper_arm_link" />
    <axis
      xyz="0 0 -1" />
    <limit
      effort="0"
      velocity="0"
      lower="-0.051"
      upper="0.983"
    />
  </joint>
  <link
    name="lower_arm_link">
    <inertial>
      <origin
        xyz="-0.090 0.390 0.028466"
        rpy="0 0 0" />
      <mass
        value="0.56692" />
      <inertia
        ixx="0.00081497"
        ixy="-3.907E-11"
        ixz="-4.0337E-18"
        iyy="0.0089538"
        iyz="-3.238E-18"
        izz="0.0087119" />
    </inertial>
    <visual>
      <origin
        xyz="-0.090 0.390 0.028466"
        rpy="0 0 0" />
      <geometry>
        <mesh
          filename="package://fedar/meshes/lower_arm_link.STL" />
      </geometry>
      <material
        name="">
        <color
          rgba="1 0.69804 0.69804 1" />
      </material>
    </visual>
    <collision>
      <origin
        xyz="-0.090 0.390 0.028466"
        rpy="0 0 0" />
      <geometry>
        <mesh
          filename="package://fedar/meshes/lower_arm_link.STL" />
      </geometry>
    </collision>
  </link>
  <joint
    name="lower_arm_joint"
    type="revolute">
    <origin
      xyz="0.4 0 0"
      rpy="-3.1416 7.8846E-16 -1.3449" />
    <parent
      link="upper_arm_link" />
    <child
      link="lower_arm_link" />
    <axis
      xyz="0 0 -1" />
    <limit
      effort="0"
      velocity="0"
      lower="-0.406"
      upper="0.320"
    />
  </joint>
  <link
    name="wrist_link">
    <inertial>
      <origin
        xyz="-0.534 0.1385 -0.035"
        rpy="0 0 0" />
      <mass
        value="0.25868" />
      <inertia
        ixx="0.0013374"
        ixy="-0.00017264"
        ixz="1.3162E-06"
        iyy="0.0010488"
        iyz="1.7858E-06"
        izz="0.0014236" />
    </inertial>
    <visual>
      <origin
        xyz="-0.534 0.1385 -0.035"
        rpy="0 0 0" />
      <geometry>
        <mesh
          filename="package://fedar/meshes/wrist_link.STL" />
      </geometry>
      <material
        name="">
        <color
          rgba="0.69804 0.69804 1 1" />
      </material>
    </visual>
    <collision>
      <origin
        xyz="-0.534 0.1385 -0.035"
        rpy="0 0 0" />
      <geometry>
        <mesh
          filename="package://fedar/meshes/wrist_link.STL" />
      </geometry>
    </collision>
  </link>
  <joint
    name="wrist_joint"
    type="revolute">
    <origin
      xyz="0.30 0 0"
      rpy="-3.1416 0 -1.0395" />
    <parent
      link="lower_arm_link" />
    <child
      link="wrist_link" />
    <axis
      xyz="0 0 1" />
    <limit
      effort="0"
      velocity="0"
      lower="-1.2"
      upper="0.57"
    />
  </joint>
  <link
    name="scoop_link">
    <inertial>
      <origin
        xyz="0.057 -0.687 0.03"
        rpy="0 0 0" />
      <mass
        value="0.12076" />
      <inertia
        ixx="0.00017125"
        ixy="-1.4964E-05"
        ixz="1.4017E-07"
        iyy="0.00029604"
        iyz="-3.6776E-08"
        izz="0.00017855" />
    </inertial>
    <visual>
      <origin
        xyz="0.057 -0.687 0.03"
        rpy="0 0 0" />
      <geometry>
        <mesh
          filename="package://fedar/meshes/scoop_link.STL" />
      </geometry>
      <material
        name="">
        <color
          rgba="1 1 0 1" />
      </material>
    </visual>
    <collision>
      <origin
        xyz="0.057 -0.687 0.03"
        rpy="0 0 0" />
      <geometry>
        <mesh
          filename="package://fedar/meshes/scoop_link.STL" />
      </geometry>
    </collision>
  </link>
  <joint
    name="scoop_joint"
    type="revolute">
    <origin
      xyz="0.12 -0.08 0"
      rpy="3.1416 0 1.3313" />
    <parent
      link="wrist_link" />
    <child
      link="scoop_link" />
    <axis
      xyz="0 0 -1" />
    <limit
      lower="-1.8025"
      upper="2.5957"
      effort="0"
      velocity="0" />
  </joint>
  <link
    name="camera_link">
    <inertial>
      <origin
        xyz="0.00019514 0.018811 0.0010567"
        rpy="1.5708 0 1.5708" />
      <mass
        value="0.54554" />
      <inertia
        ixx="0.00022589"
        ixy="3.4601E-08"
        ixz="2.5661E-06"
        iyy="0.0028794"
        iyz="-1.4752E-07"
        izz="0.00279" />
    </inertial>
    <visual>
      <origin
        xyz="0 0 0"
        rpy="2.1008 0 1.5708" />
      <geometry>
        <mesh
          filename="package://fedar/meshes/camera_link.STL" />
      </geometry>
      <material
        name="">
        <color
          rgba="0.79216 0.81961 0.93333 1" />
      </material>
    </visual>
    <collision>
      <origin
        xyz="0.00019514 0.018811 0.0010567"
        rpy="1.5708 0 1.5708" />
      <geometry>
        <mesh
          filename="package://fedar/meshes/camera_link.STL" />
      </geometry>
    </collision>
  </link>
  <joint
    name="camera_joint"
    type="fixed">
    <origin
      xyz="-0.25453 -0.15 1.204"
      rpy="0 0.7 -1.5708" />
    <parent
      link="base_link" />
    <child
      link="camera_link" />
    <axis
      xyz="0 0 0" />
  </joint>
</robot>
